<?xml version="1.0"?> 
<robot name="Derpy_Walle">
    <material name="black"> 
        <color rgba="0 0 0 1"/>
    </material>
    <material name="blue"> 
        <color rgba="0.6 0.7 0.8 1"/>
    </material>
	<material name= "red">
		<color rgba = ".8 0 0 1"/>
	</material>
	
	<link name="base_link">
        <visual> 
            <geometry> 
                <box size="0.5 0.5 0.1"/>
            </geometry>
            <material name="red"/>
        </visual>
        <inertial> 
            <mass value="50"/>
            <inertia ixx="0.2" ixy="0" ixz="0" iyy="0.2" iyz="0.0" izz="0.2"/>
        </inertial> 
		<collision> 
             <geometry> 
                <box size="0.5 0.5 0.1"/>
            </geometry>
            <origin rpy="0 0 0"/>
        </collision> 
    </link> 
	
	<link name="1top">
        <visual> 
            <geometry> 
                <cylinder length="0.5" radius="0.1"/>
            </geometry>
            <material name="black"/>
            <origin rpy="0 0 0" xyz="0 0 .25"/>
        </visual>
        <collision>
             <geometry>
                <cylinder length="0.5" radius="0.1"/>
            </geometry>
            <origin rpy="0 0 0"/>
        </collision>
        <inertial> 
            <origin rpy="0 0 0"/>
            <mass value="0.3"/>
            <inertia ixx="0.4" ixy="0" ixz="0" iyy="0.4" iyz="0.0" izz="0.2"/>
        </inertial> 
    </link>
	
	<joint name="top1_rotate" type="continuous">
        <parent link="base_link"/>
        <child link="1top"/> 
        <axis xyz="0 0 1"/>
        <origin xyz="0 0 0"/>
    </joint>
	
	<link name="2top">
        <visual> 
            <geometry> 
                <box size = ".3 .3 .5"/>
            </geometry>
            <origin rpy="0 0 0" xyz="0 0 0"/>
        </visual>
        <collision>
             <geometry>
                <box size = ".3 .3 .5"/>
            </geometry>
            <origin rpy="0 0 0"/>
        </collision>
            <material name="blue"/>
        <inertial> 
            <origin rpy="0 0 0"/>
            <mass value="0.3"/>
            <inertia ixx="0.4" ixy="0" ixz="0" iyy="0.4" iyz="0.0" izz="0.2"/>
        </inertial> 
    </link>
	
	<joint name="top2_rotate" type="continuous">
        <parent link="1top"/>
        <child link="2top"/>
        <axis xyz="0 1 0"/>
		<origin xyz="0 0 .5"/>
    </joint>
	
	<link name="3top">
        <visual> 
            <geometry> 
                <box size = ".2 .2 .5"/>
            </geometry>

            <material name="red"/>
        </visual>
        <collision>
             <geometry>
                <box size = ".2 .2 .5"/>
            </geometry>
            <origin rpy="0 0 0"/>
        </collision>
        <inertial> 
            <origin rpy="0 0 0"/>
            <mass value="0.3"/>
            <inertia ixx="0.4" ixy="0" ixz="0" iyy="0.4" iyz="0.0" izz="0.2"/>
        </inertial> 
    </link>
	
	<joint name="top3_rotate" type="continuous">
        <parent link="2top"/>
        <child link="3top"/>
        <axis xyz="1 0 0"/>
		<origin xyz="0 0 .5"/>
    </joint>

    <link name="end-effector1">
        <visual>
            <geometry>
                <box size = ".05 .1 .2"/>
            </geometry>
            <material name="black"/>
        </visual>
        <collision>
             <geometry>
                <box size = ".05 .1 .2"/>
            </geometry>
            <origin rpy="0 0 0"/>
        </collision>
        <inertial>
            <origin rpy="0 0 0"/>
            <mass value="0.1"/>
            <inertia ixx="0.1" ixy="0" ixz="0" iyy="0.1" iyz="0.0" izz="0.1"/>
        </inertial>
    </link>

    <joint name="end-effector-joint1" type="fixed">
        <parent link="3top"/>
        <child link="end-effector1"/>
        <axis xyz="0 0 0"/>
		<origin xyz="-.05 0 .3"/>
    </joint>

    <link name="end-effector2">
        <visual>
            <geometry>
                <box size = ".05 .1 .2"/>
            </geometry>
            <material name="black"/>
        </visual>
        <collision>
             <geometry>
                <box size = ".05 .1 .2"/>
            </geometry>
            <origin rpy="0 0 0"/>
        </collision>
        <inertial>
            <origin rpy="0 0 0"/>
            <mass value="0.1"/>
            <inertia ixx="0.1" ixy="0" ixz="0" iyy="0.1" iyz="0.0" izz="0.1"/>
        </inertial>
    </link>

    <joint name="end-effector-joint2" type="fixed">
        <parent link="3top"/>
        <child link="end-effector2"/>
        <axis xyz="0 0 0"/>
		<origin xyz=".05 0 .3"/>
    </joint>

</robot>